Workbook

Sheet Tabla de Cálculos para Energía 
A1: ZONAS HOSPITALARIAS | D1: ENERGÍA TÉRMICA
A2: Área/Descripción | B2: Criticidad | C2: Área (m²) | D2: Potencia de diseño (BTU/h) | E2: Potencia de diseño (TR) | F2: Simultaneidad | G2: Potencia Efectiva (TR) | H2: Categoría/Zona Hospitalaria | I2: EFLH (h/año) | K2: Demanda Anual (TR-h) | L2: MW-h | N2: Mes | O2: CDD 18 (°C-días) | P2: Fracción | Q2: Energía Térmica HVAC/CaaS (MWh) | R2: COP | S2: Energía Eléctrica HVAC/CaaS (MWh) | T2: Consumo Bombas Primarias + Secundarias (GWh) | U2: Subtotal PAH | V2: Consumo Motores UTAs/AHUs (GWh) | W2: Resto Cargas (MWh) | X2: Subtotal No Hvac | Y2: Total Eléctrico (MWh) | Z2: Porcentaje Energía No HVAC / Energía HVAC | AA2: Porcentaje Energía HVAC / Energía Total | AC2: Categoría/Zona Hospitalaria | AD2: Superficie (m2) | AE2: Carga Térmica de Diseño | AF2: EFLH Calculado (h/año) | AG2: EFLH Ponderado (h/año) | AH2: Justificación (basado en ASHRAE 170 y operación)
A3: Hospitalización Norte P1 | B3: =IF(F3=0.9,"Crítica",IF(F3=0.8,"Semicrítica","General")) -> Crítica | C3: 958 | D3: 934000 | E3: =D3/12000 -> 77.833333 | F3: 0.9 | G3: =E3*F3 -> 70.05 | H3: Hospitalización | I3: 5000 | K3: =E3*F3*I3 -> 350250 | L3: =K3*3.517/1000 -> 1231.8293 | N3: Ene | O3: 275.55 | P3: =O3/$O$15 -> 0.090790774 | Q3: =P3*$L$27 -> 1104.3706 | R3: 3 | S3: =Q3/R3/1000 -> 0.36812354 | T3: 0.035 | U3: =S3+T3 -> 0.40312354 | V3: 0.146 | W3: ='Cálculo Energético Resto no HVAC'!$C$17/1000 -> #REF! | X3: =V3+W3 -> #REF! | Y3: =S3+W3 -> #REF! | Z3: =W3/S3 -> #REF! | AA3: =S3/Y3 -> #REF! | AC3: Hospitalización | AD3: 3885 | AE3: 263.58 | AF3: =365*14*0.981 -> 5012.91 | AG3: 5000 | AH3: Operación media (14-16 h/día efectivo, de ASHRAE Handbook Ch.9 para wards con setback nocturno), ACH 4-6, confort general (22°C, 50% RH). PLF 0.98 por cargas internas constantes en tropical (Wan et al., 2017).
A4: Hospitalización Norte P2 | B4: =IF(F4=0.9,"Crítica",IF(F4=0.8,"Semicrítica","General")) -> Crítica | C4: 1128 | D4: 924000 | E4: =D4/12000 -> 77 | F4: 0.9 | G4: =E4*F4 -> 69.3 | H4: Hospitalización | I4: 5000 | K4: =E4*F4*I4 -> 346500 | L4: =K4*3.517/1000 -> 1218.6405 | N4: Feb | O4: 270.95 | P4: =O4/$O$15 -> 0.089275124 | Q4: =P4*$L$27 -> 1085.9344 | R4: 3 | S4: =Q4/R4/1000 -> 0.36197813 | T4: 0.025 | U4: =S4+T4 -> 0.38697813 | V4: 0.104 | W4: ='Cálculo Energético Resto no HVAC'!$C$17/1000 -> #REF! | X4: =V4+W4 -> #REF! | Y4: =S4+W4 -> #REF! | Z4: =W4/S4 -> #REF! | AA4: =S4/Y4 -> #REF! | AC4: Emergencia/Recuperación | AD4: 1519 | AE4: 84.92 | AF4: =365*16*1 -> 5840 | AG4: 6000 | AH4: 24/7 (ASHRAE Handbook Ch.9 implica operación continua), presión variable, ACH 12+. PLF 1.0 por demanda constante en áreas críticas.
A5: Hospitalización Sur P1 | B5: =IF(F5=0.9,"Crítica",IF(F5=0.8,"Semicrítica","General")) -> Crítica | C5: 867 | D5: 604000 | E5: =D5/12000 -> 50.333333 | F5: 0.9 | G5: =E5*F5 -> 45.3 | H5: Hospitalización | I5: 5000 | K5: =E5*F5*I5 -> 226500 | L5: =K5*3.517/1000 -> 796.6005 | N5: Mar | O5: 296.7 | P5: =O5/$O$15 -> 0.097759473 | Q5: =P5*$L$27 -> 1189.1372 | R5: 3 | S5: =Q5/R5/1000 -> 0.39637908 | T5: 0.035 | U5: =S5+T5 -> 0.43137908 | V5: 0.146 | W5: ='Cálculo Energético Resto no HVAC'!$C$17/1000 -> #REF! | X5: =V5+W5 -> #REF! | Y5: =S5+W5 -> #REF! | Z5: =W5/S5 -> #REF! | AA5: =S5/Y5 -> #REF! | AC5: Quirófanos/Procedimientos | AD5: 463 | AE5: 89.92 | AF5: =365*16*1 -> 5840 | AG5: 6000 | AH5: HEPA, ACH 20-25, esterilidad constante (ASHRAE Handbook Ch.9: uso 8-12 h/día típico, ajustado a 16 h efectivo con setback). PLF 1.0 por ventilación mínima continua.
A6: Hospitalización Sur P2 | B6: =IF(F6=0.9,"Crítica",IF(F6=0.8,"Semicrítica","General")) -> Crítica | C6: 932 | D6: 701000 | E6: =D6/12000 -> 58.416667 | F6: 0.9 | G6: =E6*F6 -> 52.575 | H6: Hospitalización | I6: 5000 | K6: =E6*F6*I6 -> 262875 | L6: =K6*3.517/1000 -> 924.53138 | N6: Abr | O6: 281.05 | P6: =O6/$O$15 -> 0.092602965 | Q6: =P6*$L$27 -> 1126.4139 | R6: 3 | S6: =Q6/R6/1000 -> 0.37547131 | T6: 0.033 | U6: =S6+T6 -> 0.40847131 | V6: 0.137 | W6: ='Cálculo Energético Resto no HVAC'!$C$17/1000 -> #REF! | X6: =V6+W6 -> #REF! | Y6: =S6+W6 -> #REF! | Z6: =W6/S6 -> #REF! | AA6: =S6/Y6 -> #REF! | AC6: Labs/Esterilización | AD6: =531+1740 -> 2271 | AE6: =39.92+104.33 -> 144.25 | AF6: =365*15*0.99 -> 5420.25 | AG6: 5400 | AH6: ACH 10, presión negativa, filtración MERV 16 (ASHRAE Handbook Ch.9: operación extendida para control de contaminantes). PLF 0.99 por cargas internas altas en tropical.
A7: Emergencia | B7: =IF(F7=0.9,"Crítica",IF(F7=0.8,"Semicrítica","General")) -> Semicrítica | C7: 844 | D7: 593000 | E7: =D7/12000 -> 49.416667 | F7: 0.8 | G7: =E7*F7 -> 39.533333 | H7: Emergencia/Recuperación | I7: 6000 | K7: =E7*F7*I7 -> 237200 | L7: =K7*3.517/1000 -> 834.2324 | N7: May | O7: 276.45 | P7: =O7/$O$15 -> 0.091087315 | Q7: =P7*$L$27 -> 1107.9777 | R7: 3 | S7: =Q7/R7/1000 -> 0.3693259 | T7: 0.025 | U7: =S7+T7 -> 0.3943259 | V7: 0.102 | W7: ='Cálculo Energético Resto no HVAC'!$C$17/1000 -> #REF! | X7: =V7+W7 -> #REF! | Y7: =S7+W7 -> #REF! | Z7: =W7/S7 -> #REF! | AA7: =S7/Y7 -> #REF! | AC7: Cafetería/Hall | AD7: 781 | AE7: 76.93 | AF7: =365*10.5*0.99 -> 3794.175 | AG7: 3800 | AH7: Intermitente (ASHRAE Handbook Ch.9: alineado con horarios de comida, ~10-12 h/día), ventilación básica (MERV 8+14). PLF 0.99 por operación diurna en tropical.
A8: Cafetería | B8: =IF(F8=0.9,"Crítica",IF(F8=0.8,"Semicrítica","General")) -> General | C8: 435 | D8: 338000 | E8: =D8/12000 -> 28.166667 | F8: 0.7 | G8: =E8*F8 -> 19.716667 | H8: Cafetería/Hall | I8: 3800 | K8: =E8*F8*I8 -> 74923.333 | L8: =K8*3.517/1000 -> 263.50536 | N8: Jun | O8: 221.15 | P8: =O8/$O$15 -> 0.072866557 | Q8: =P8*$L$27 -> 886.34209 | R8: 3 | S8: =Q8/R8/1000 -> 0.29544736 | T8: 0.015 | U8: =S8+T8 -> 0.31044736 | V8: 0.061 | W8: ='Cálculo Energético Resto no HVAC'!$C$17/1000 -> #REF! | X8: =V8+W8 -> #REF! | Y8: =S8+W8 -> #REF! | Z8: =W8/S8 -> #REF! | AA8: =S8/Y8 -> #REF! | AC8: Mantenimiento/Servicios | AD8: 1440 | AE8: 147.24 | AF8: =((AD3*AF3)+(AD4*AF4)+(AD5*AF5)+(AD6*AF6)+(AD7*AF7))/C27 -> 4471.7322 | AG8: =((AD3*AG3)+(AD4*AG4)+(AD5*AG5)+(AD6*AG6)+(AD7*AG7))/C27 -> 4493.5032 | AH8: Ajustado por clima tropical y ASHRAE 170. Coherente: Alto pero realista para Guayas (clima constante + ventilación alta). ASHRAE Handbook Ch.18 (tropical): 4,800-5,800 h promedio hospitales con alta latente.
A9: Imagenología | B9: =IF(F9=0.9,"Crítica",IF(F9=0.8,"Semicrítica","General")) -> Semicrítica | C9: 1060 | D9: 858000 | E9: =D9/12000 -> 71.5 | F9: 0.8 | G9: =E9*F9 -> 57.2 | H9: Labs/Esterilización | I9: 5400 | K9: =E9*F9*I9 -> 308880 | L9: =K9*3.517/1000 -> 1086.331 | N9: Jul | O9: 240.45 | P9: =O9/$O$15 -> 0.0792257 | Q9: =P9*$L$27 -> 963.69412 | R9: 3 | S9: =Q9/R9/1000 -> 0.32123137 | T9: 0.018 | U9: =S9+T9 -> 0.33923137 | V9: 0.073 | W9: ='Cálculo Energético Resto no HVAC'!$C$17/1000 -> #REF! | X9: =V9+W9 -> #REF! | Y9: =S9+W9 -> #REF! | Z9: =W9/S9 -> #REF! | AA9: =S9/Y9 -> #REF! | AC9: Total | AD9: =sum(AD3:AD8) -> 10359 | AE9: =SUM(AE3:AE8) -> 806.84 | AF9: =($AD3*AF3+$AD4*AF4+$AD5*AF5+$AD6*AF6+$AD7*AF7+$AD8*AF8)/$AD9 -> 5093.3457 | AG9: =($AD3*AG3+$AD4*AG4+$AD5*AG5+$AD6*AG6+$AD7*AG7+$AD8*AG8)/$AD9 -> 5118.1431
A10: Mantenimiento/Morgue | B10: =IF(F10=0.9,"Crítica",IF(F10=0.8,"Semicrítica","General")) -> Semicrítica | C10: 510 | D10: 757000 | E10: =D10/12000 -> 63.083333 | F10: 0.8 | G10: =E10*F10 -> 50.466667 | H10: Mantenimiento/Servicios | I10: 5400 | K10: =E10*F10*I10 -> 272520 | L10: =K10*3.517/1000 -> 958.45284 | N10: Ago | O10: 218.65 | P10: =O10/$O$15 -> 0.072042834 | Q10: =P10*$L$27 -> 876.32239 | R10: 3 | S10: =Q10/R10/1000 -> 0.29210746 | T10: 0.016 | U10: =S10+T10 -> 0.30810746 | V10: 0.067 | W10: ='Cálculo Energético Resto no HVAC'!$C$17/1000 -> #REF! | X10: =V10+W10 -> #REF! | Y10: =S10+W10 -> #REF! | Z10: =W10/S10 -> #REF! | AA10: =S10/Y10 -> #REF!
A11: Servicios | B11: =IF(F11=0.9,"Crítica",IF(F11=0.8,"Semicrítica","General")) -> Semicrítica | C11: 660 | D11: 796000 | E11: =D11/12000 -> 66.333333 | F11: 0.8 | G11: =E11*F11 -> 53.066667 | H11: Mantenimiento/Servicios | I11: 5400 | K11: =E11*F11*I11 -> 286560 | L11: =K11*3.517/1000 -> 1007.8315 | N11: Sep | O11: 214.45 | P11: =O11/$O$15 -> 0.070658979 | Q11: =P11*$L$27 -> 859.48931 | R11: 3 | S11: =Q11/R11/1000 -> 0.28649644 | T11: 0.013 | U11: =S11+T11 -> 0.29949644 | V11: 0.054 | W11: ='Cálculo Energético Resto no HVAC'!$C$17/1000 -> #REF! | X11: =V11+W11 -> #REF! | Y11: =S11+W11 -> #REF! | Z11: =W11/S11 -> #REF! | AA11: =S11/Y11 -> #REF!
A12: Hall Principal | B12: =IF(F12=0.9,"Crítica",IF(F12=0.8,"Semicrítica","General")) -> General | C12: 180 | D12: 272000 | E12: =D12/12000 -> 22.666667 | F12: 0.7 | G12: =E12*F12 -> 15.866667 | H12: Cafetería/Hall | I12: 3800 | K12: =E12*F12*I12 -> 60293.333 | L12: =K12*3.517/1000 -> 212.05165 | N12: Oct | O12: 224.35 | P12: =O12/$O$15 -> 0.073920923 | Q12: =P12*$L$27 -> 899.1673 | R12: 3 | S12: =Q12/R12/1000 -> 0.29972243 | T12: 0.018 | U12: =S12+T12 -> 0.31772243 | V12: 0.073 | W12: ='Cálculo Energético Resto no HVAC'!$C$17/1000 -> #REF! | X12: =V12+W12 -> #REF! | Y12: =S12+W12 -> #REF! | Z12: =W12/S12 -> #REF! | AA12: =S12/Y12 -> #REF!
A13: Comedor | B13: =IF(F13=0.9,"Crítica",IF(F13=0.8,"Semicrítica","General")) -> General | C13: 116 | D13: 185000 | E13: =D13/12000 -> 15.416667 | F13: 0.7 | G13: =E13*F13 -> 10.791667 | H13: Cafetería/Hall | I13: 3800 | K13: =E13*F13*I13 -> 41008.333 | L13: =K13*3.517/1000 -> 144.22631 | N13: Nov | O13: 233.9 | P13: =O13/$O$15 -> 0.077067545 | Q13: =P13*$L$27 -> 937.44253 | R13: 3 | S13: =Q13/R13/1000 -> 0.31248084 | T13: 0.015 | U13: =S13+T13 -> 0.32748084 | V13: 0.061 | W13: ='Cálculo Energético Resto no HVAC'!$C$17/1000 -> #REF! | X13: =V13+W13 -> #REF! | Y13: =S13+W13 -> #REF! | Z13: =W13/S13 -> #REF! | AA13: =S13/Y13 -> #REF! | AD13: Zona Hospitalaria | AE13: Superficie (m²) | AF13: Carga Térmica de Diseño Nominal (TR)
A14: Farmacia | B14: =IF(F14=0.9,"Crítica",IF(F14=0.8,"Semicrítica","General")) -> Semicrítica | C14: 680 | D14: 394000 | E14: =D14/12000 -> 32.833333 | F14: 0.8 | G14: =E14*F14 -> 26.266667 | H14: Labs/Esterilización | I14: 5400 | K14: =E14*F14*I14 -> 141840 | L14: =K14*3.517/1000 -> 498.85128 | N14: Dic | O14: 281.35 | P14: =O14/$O$15 -> 0.092701812 | Q14: =P14*$L$27 -> 1127.6163 | R14: 3 | S14: =Q14/R14/1000 -> 0.3758721 | T14: 0.025 | U14: =S14+T14 -> 0.4008721 | V14: 0.102 | W14: ='Cálculo Energético Resto no HVAC'!$C$17/1000 -> #REF! | X14: =V14+W14 -> #REF! | Y14: =S14+W14 -> #REF! | Z14: =W14/S14 -> #REF! | AA14: =S14/Y14 -> #REF! | AD14: Hospitalización | AE14: 3885 | AF14: 263.58
A15: Esterilización | B15: =IF(F15=0.9,"Crítica",IF(F15=0.8,"Semicrítica","General")) -> Semicrítica | C15: 320 | D15: 251000 | E15: =D15/12000 -> 20.916667 | F15: 0.8 | G15: =E15*F15 -> 16.733333 | H15: Labs/Esterilización | I15: 5400 | K15: =E15*F15*I15 -> 90360 | L15: =K15*3.517/1000 -> 317.79612 | N15: Total | O15: =SUM(O3:O14) -> 3035 | P15: =sum(P3:P14) -> 1 | Q15: =sum(Q3:Q14) -> 12163.908 | S15: =sum(S3:S14) -> 4.054636 | T15: 0.273 | U15: =S15+T15 -> 4.327636 | V15: =sum(V3:V14) -> 1.126 | W15: =sum(W3:W14) -> #REF! | X15: =V15+W15 -> #REF! | Y15: =sum(Y3:Y14) -> #REF! | AA15: =AVERAGE(AA3:AA14) -> #REF! | AD15: Emergencia/Recuperación | AE15: 1519 | AF15: 84.92 | AH15: =ROUNDDOWN(2.5, 2) -> 2.5
A16: Procedimientos | B16: =IF(F16=0.9,"Crítica",IF(F16=0.8,"Semicrítica","General")) -> Semicrítica | C16: 186 | D16: 380000 | E16: =D16/12000 -> 31.666667 | F16: 0.8 | G16: =E16*F16 -> 25.333333 | H16: Quirófanos/Procedimientos | I16: 6000 | K16: =E16*F16*I16 -> 152000 | L16: =K16*3.517/1000 -> 534.584 | Y16: Notas | Z16: Benchmark JBGHY ratio | AD16: Quirófanos/Procedimientos | AE16: 463 | AF16: 89.92 | AH16: =FLOOR(2.5,2) -> 2
A17: Recuperación | B17: =IF(F17=0.9,"Crítica",IF(F17=0.8,"Semicrítica","General")) -> Semicrítica | C17: 675 | D17: 426000 | E17: =D17/12000 -> 35.5 | F17: 0.8 | G17: =E17*F17 -> 28.4 | H17: Emergencia/Recuperación | I17: 6000 | K17: =E17*F17*I17 -> 170400 | L17: =K17*3.517/1000 -> 599.2968 | W17: 2547 | Z17: Superficie cuarto de máquinas | AD17: Labs/Esterilización | AE17: 371 | AF17: 32.33
A18: Corredor Sucio | B18: =IF(F18=0.9,"Crítica",IF(F18=0.8,"Semicrítica","General")) -> Semicrítica | C18: 270 | D18: 214000 | E18: =D18/12000 -> 17.833333 | F18: 0.8 | G18: =E18*F18 -> 14.266667 | H18: Mantenimiento/Servicios | I18: 5400 | K18: =E18*F18*I18 -> 77040 | L18: =K18*3.517/1000 -> 270.94968 | AD18: Cafetería/Hall | AE18: 781 | AF18: 76.93
A19: Laboratorio | B19: =IF(F19=0.9,"Crítica",IF(F19=0.8,"Semicrítica","General")) -> Semicrítica | C19: 101 | D19: 137000 | E19: =D19/12000 -> 11.416667 | F19: 0.8 | G19: =E19*F19 -> 9.1333333 | H19: Labs/Esterilización | I19: 5400 | K19: =E19*F19*I19 -> 49320 | L19: =K19*3.517/1000 -> 173.45844 | AD19: Mantenimiento/Servicios | AE19: 1170 | AF19: 147.24
A20: Curettage | B20: =IF(F20=0.9,"Crítica",IF(F20=0.8,"Semicrítica","General")) -> Semicrítica | C20: 33 | D20: 87000 | E20: =D20/12000 -> 7.25 | F20: 0.8 | G20: =E20*F20 -> 5.8 | H20: Quirófanos/Procedimientos | I20: 6000 | K20: =E20*F20*I20 -> 34800 | L20: =K20*3.517/1000 -> 122.3916 | N20: Enero | O20: 275.55 | AD20: Imagenología/Farmacia | AE20: 1740 | AF20: 104.33
A21: General OR | B21: =IF(F21=0.9,"Crítica",IF(F21=0.8,"Semicrítica","General")) -> General | C21: 76 | D21: 176000 | E21: =D21/12000 -> 14.666667 | F21: 0.7 | G21: =E21*F21 -> 10.266667 | H21: Quirófanos/Procedimientos | I21: 6000 | K21: =E21*F21*I21 -> 61600 | L21: =K21*3.517/1000 -> 216.6472 | N21: Febrero | O21: 270.95 | AD21: Total | AE21: 10358 | AF21: 806.8
A22: Large OR | B22: =IF(F22=0.9,"Crítica",IF(F22=0.8,"Semicrítica","General")) -> General | C22: 76 | D22: 176000 | E22: =D22/12000 -> 14.666667 | F22: 0.7 | G22: =E22*F22 -> 10.266667 | H22: Quirófanos/Procedimientos | I22: 6000 | K22: =E22*F22*I22 -> 61600 | L22: =K22*3.517/1000 -> 216.6472 | N22: Marzo | O22: 296.7 | Q22: Mes | R22: Demanda Térmica (GWh) | S22: Consumo Chillers (GWh) | W22: Consumo Bombas Primarias + Secundarias (GWh) | Y22: Consumo Motores UTAs/AHUs (GWh) | Z22: Consumo Resto no-HVAC (GWh) | AA22: Total Consumo Planta (GWh)
A23: Clean Procedures | B23: =IF(F23=0.9,"Crítica",IF(F23=0.8,"Semicrítica","General")) -> General | C23: 46 | D23: 130000 | E23: =D23/12000 -> 10.833333 | F23: 0.7 | G23: =E23*F23 -> 7.5833333 | H23: Quirófanos/Procedimientos | I23: 6000 | K23: =E23*F23*I23 -> 45500 | L23: =K23*3.517/1000 -> 160.0235 | N23: Abril | O23: 281.05 | Q23: Ene | R23: 1.236 | S23: =R23/3 -> 0.412 | W23: 0.035 | Y23: 0.146 | Z23: 0.118 | AA23: 0.704
A24: Dirty Procedures | B24: =IF(F24=0.9,"Crítica",IF(F24=0.8,"Semicrítica","General")) -> General | C24: 46 | D24: 130000 | E24: =D24/12000 -> 10.833333 | F24: 0.7 | G24: =E24*F24 -> 7.5833333 | H24: Quirófanos/Procedimientos | I24: 6000 | K24: =E24*F24*I24 -> 45500 | L24: =K24*3.517/1000 -> 160.0235 | N24: Mayo | O24: 276.45 | Q24: Feb | R24: 1.019 | S24: 0.334 | W24: 0.025 | Y24: 0.104 | Z24: 0.118 | AA24: 0.581
A25: Zona Estéril | B25: =IF(F25=0.9,"Crítica",IF(F25=0.8,"Semicrítica","General")) -> Semicrítica | C25: 110 | D25: 91000 | E25: =D25/12000 -> 7.5833333 | F25: 0.8 | G25: =E25*F25 -> 6.0666667 | H25: Labs/Esterilización | I25: 5400 | K25: =E25*F25*I25 -> 32760 | L25: =K25*3.517/1000 -> 115.21692 | N25: Junio | O25: 221.15 | Q25: Mar | R25: 1.236 | S25: 0.405 | W25: 0.035 | Y25: 0.146 | Z25: 0.118 | AA25: 0.704
A26: Terraza-FC | B26: =IF(F26=0.9,"Crítica",IF(F26=0.8,"Semicrítica","General")) -> General | C26: 50 | D26: 128000 | E26: =D26/12000 -> 10.666667 | F26: 0.7 | G26: =E26*F26 -> 7.4666667 | H26: Cafetería/Hall | I26: 3800 | K26: =E26*F26*I26 -> 28373.333 | L26: =K26*3.517/1000 -> 99.789013 | N26: Julio | O26: 240.45 | Q26: Abr | R26: 1.183 | S26: 0.388 | W26: 0.033 | Y26: 0.137 | Z26: 0.118 | AA26: 0.676
A27: Total | C27: =sum(C3:C26) -> 10359 | D27: 9682000 | E27: =SUM(E3:E26) -> 806.83333 | F27: =AVERAGE(F3:F26) -> 0.78333333 | G27: =E27*F27 -> 632.01944 | I27: 9 | K27: =sum(K3:K26) -> 3458603.3 | L27: =SUM(L3:L26) -> 12163.908 | M27: =K27*3.517/1000 -> 12163.908 | N27: Agosto | O27: 218.65 | Q27: May | R27: 1.076 | S27: 0.353 | W27: 0.025 | Y27: 0.102 | Z27: 0.118 | AA27: 0.598
F28: 0.75 | G28: =E27*F28 -> 605.125 | I28: 6281.8 | L28: =K28*3.517/1000 -> 0 | M28: =K28*3.517/1000 -> 0 | N28: Septiembre | O28: 214.45 | Q28: Jun | R28: 0.86 | S28: 0.282 | W28: 0.015 | Y28: 0.061 | Z28: 0.118 | AA28: 0.476
F29: 0.85 | G29: =E27*F29 -> 685.80833 | I29: =AVERAGE(I5:I28) -> 5112.1167 | K29: =I27*G29 -> 6172.275 | N29: Octubre | O29: 224.35 | Q29: Jul | R29: 0.944 | S29: 0.31 | W29: 0.018 | Y29: 0.073 | Z29: 0.118 | AA29: 0.519
I30: 6718.15 | N30: Noviembre | O30: 233.9 | Q30: Ago | R30: 0.909 | S30: 0.298 | W30: 0.016 | Y30: 0.067 | Z30: 0.118 | AA30: 0.499
G31: =G27/E27 -> 0.78333333 | K31: 3396741.7 | L31: =K31*3.517/1000 -> 11946.341 | N31: Diciembre | O31: 281.35 | Q31: Sep | R31: 0.818 | S31: 0.268 | W31: 0.013 | Y31: 0.054 | Z31: 0.118 | AA31: 0.453
Q32: Oct | R32: 0.944 | S32: 0.31 | W32: 0.018 | Y32: 0.073 | Z32: 0.118 | AA32: 0.519
J33: 693.11 | Q33: Nov | R33: 0.86 | S33: 0.282 | W33: 0.015 | Y33: 0.061 | Z33: 0.118 | AA33: 0.476
J34: 5827.46 | Q34: Dic | R34: 1.076 | S34: 0.353 | W34: 0.025 | Y34: 0.102 | Z34: 0.118 | AA34: 0.598
A35: Hora | B35: Carga Térmica Operacional (TR) | I35: =J33*J34 -> 4039070.8 | P35: Total Anual | Q35: 12.164 | R35: 3.988 | V35: 0.273 | X35: 1.126 | Y35: 1.416 | Z35: 6.803
A36: 0 | B36: 378
A37: 0.083333333 | B37: 346 | I37: 404085
A38: 0.16666667 | B38: 315 | I38: 361547
A39: 0.25 | B39: 378 | I39: 406847
A40: 0.33333333 | B40: 472 | I40: 400052
...
